[2022-09-23T20:52:00.911+0000] {taskinstance.py:1165} INFO - Dependencies all met for <TaskInstance: loading_data_remote.load_traj_tables_remote manual__2022-09-23T20:49:39.808876+00:00 [queued]>
[2022-09-23T20:52:01.071+0000] {taskinstance.py:1165} INFO - Dependencies all met for <TaskInstance: loading_data_remote.load_traj_tables_remote manual__2022-09-23T20:49:39.808876+00:00 [queued]>
[2022-09-23T20:52:01.071+0000] {taskinstance.py:1362} INFO - 
--------------------------------------------------------------------------------
[2022-09-23T20:52:01.071+0000] {taskinstance.py:1363} INFO - Starting attempt 1 of 1
[2022-09-23T20:52:01.072+0000] {taskinstance.py:1364} INFO - 
--------------------------------------------------------------------------------
[2022-09-23T20:52:01.147+0000] {taskinstance.py:1383} INFO - Executing <Task(PythonOperator): load_traj_tables_remote> on 2022-09-23 20:49:39.808876+00:00
[2022-09-23T20:52:01.179+0000] {standard_task_runner.py:54} INFO - Started process 7593 to run task
[2022-09-23T20:52:01.182+0000] {standard_task_runner.py:82} INFO - Running: ['***', 'tasks', 'run', 'loading_data_remote', 'load_traj_tables_remote', 'manual__2022-09-23T20:49:39.808876+00:00', '--job-id', '138', '--raw', '--subdir', 'DAGS_FOLDER/load_data_remote.py', '--cfg-path', '/tmp/tmpinhun4nn']
[2022-09-23T20:52:01.183+0000] {standard_task_runner.py:83} INFO - Job 138: Subtask load_traj_tables_remote
[2022-09-23T20:52:01.196+0000] {dagbag.py:525} INFO - Filling up the DagBag from /opt/***/dags/load_data_remote.py
[2022-09-23T23:29:52.895+0000] {timeout.py:68} ERROR - Process timed out, PID: 7593
[2022-09-23T23:29:53.476+0000] {dagbag.py:330} ERROR - Failed to import: /opt/***/dags/load_data_remote.py
Traceback (most recent call last):
  File "/home/airflow/.local/lib/python3.7/site-packages/airflow/models/dagbag.py", line 326, in parse
    loader.exec_module(new_module)
  File "<frozen importlib._bootstrap_external>", line 728, in exec_module
  File "<frozen importlib._bootstrap>", line 219, in _call_with_frames_removed
  File "/opt/airflow/dags/load_data_remote.py", line 17, in <module>
    import pandas as pd
  File "/home/airflow/.local/lib/python3.7/site-packages/pandas/__init__.py", line 50, in <module>
    from pandas.core.api import (
  File "/home/airflow/.local/lib/python3.7/site-packages/pandas/core/api.py", line 29, in <module>
    from pandas.core.arrays import Categorical
  File "/home/airflow/.local/lib/python3.7/site-packages/pandas/core/arrays/__init__.py", line 20, in <module>
    from pandas.core.arrays.string_arrow import ArrowStringArray
  File "/home/airflow/.local/lib/python3.7/site-packages/pandas/core/arrays/string_arrow.py", line 65, in <module>
    import pyarrow.compute as pc
  File "/home/airflow/.local/lib/python3.7/site-packages/pyarrow/compute.py", line 18, in <module>
    from pyarrow._compute import (  # noqa
  File "/home/airflow/.local/lib/python3.7/site-packages/airflow/utils/timeout.py", line 69, in handle_timeout
    raise AirflowTaskTimeout(self.error_message)
airflow.exceptions.AirflowTaskTimeout: DagBag import timeout for /opt/***/dags/load_data_remote.py after 30.0s.
Please take a look at these docs to improve your DAG import time:
* https://***.apache.org/docs/apache-***/2.4.0/best-practices.html#top-level-python-code
* https://***.apache.org/docs/apache-***/2.4.0/best-practices.html#reducing-dag-complexity, PID: 7593
[2022-09-23T23:29:56.651+0000] {standard_task_runner.py:107} ERROR - Failed to execute job 138 for task load_traj_tables_remote (Dag 'loading_data_remote' could not be found; either it does not exist or it failed to parse.; 7593)
[2022-09-23T23:29:52.798+0000] {base_job.py:232} ERROR - LocalTaskJob heartbeat got an exception
Traceback (most recent call last):
  File "/home/airflow/.local/lib/python3.7/site-packages/sqlalchemy/engine/base.py", line 3243, in _wrap_pool_connect
    return fn()
  File "/home/airflow/.local/lib/python3.7/site-packages/sqlalchemy/pool/base.py", line 310, in connect
    return _ConnectionFairy._checkout(self)
  File "/home/airflow/.local/lib/python3.7/site-packages/sqlalchemy/pool/base.py", line 868, in _checkout
    fairy = _ConnectionRecord.checkout(pool)
  File "/home/airflow/.local/lib/python3.7/site-packages/sqlalchemy/pool/base.py", line 476, in checkout
    rec = pool._do_get()
  File "/home/airflow/.local/lib/python3.7/site-packages/sqlalchemy/pool/impl.py", line 256, in _do_get
    return self._create_connection()
  File "/home/airflow/.local/lib/python3.7/site-packages/sqlalchemy/pool/base.py", line 256, in _create_connection
    return _ConnectionRecord(self)
  File "/home/airflow/.local/lib/python3.7/site-packages/sqlalchemy/pool/base.py", line 371, in __init__
    self.__connect()
  File "/home/airflow/.local/lib/python3.7/site-packages/sqlalchemy/pool/base.py", line 666, in __connect
    pool.logger.debug("Error on connect(): %s", e)
  File "/home/airflow/.local/lib/python3.7/site-packages/sqlalchemy/util/langhelpers.py", line 72, in __exit__
    with_traceback=exc_tb,
  File "/home/airflow/.local/lib/python3.7/site-packages/sqlalchemy/util/compat.py", line 207, in raise_
    raise exception
  File "/home/airflow/.local/lib/python3.7/site-packages/sqlalchemy/pool/base.py", line 661, in __connect
    self.dbapi_connection = connection = pool._invoke_creator(self)
  File "/home/airflow/.local/lib/python3.7/site-packages/sqlalchemy/engine/create.py", line 590, in connect
    return dialect.connect(*cargs, **cparams)
  File "/home/airflow/.local/lib/python3.7/site-packages/sqlalchemy/engine/default.py", line 584, in connect
    return self.dbapi.connect(*cargs, **cparams)
  File "/home/airflow/.local/lib/python3.7/site-packages/psycopg2/__init__.py", line 122, in connect
    conn = _connect(dsn, connection_factory=connection_factory, **kwasync)
psycopg2.OperationalError: could not translate host name "postgres" to address: Temporary failure in name resolution


The above exception was the direct cause of the following exception:

Traceback (most recent call last):
  File "/home/airflow/.local/lib/python3.7/site-packages/airflow/jobs/base_job.py", line 222, in heartbeat
    session.merge(self)
  File "/home/airflow/.local/lib/python3.7/site-packages/sqlalchemy/orm/session.py", line 2961, in merge
    _resolve_conflict_map=_resolve_conflict_map,
  File "/home/airflow/.local/lib/python3.7/site-packages/sqlalchemy/orm/session.py", line 3039, in _merge
    options=options,
  File "/home/airflow/.local/lib/python3.7/site-packages/sqlalchemy/orm/session.py", line 2775, in get
    identity_token=identity_token,
  File "/home/airflow/.local/lib/python3.7/site-packages/sqlalchemy/orm/session.py", line 2878, in _get_impl
    load_options=load_options,
  File "/home/airflow/.local/lib/python3.7/site-packages/sqlalchemy/orm/loading.py", line 534, in load_on_pk_identity
    bind_arguments=bind_arguments,
  File "/home/airflow/.local/lib/python3.7/site-packages/sqlalchemy/orm/session.py", line 1688, in execute
    conn = self._connection_for_bind(bind)
  File "/home/airflow/.local/lib/python3.7/site-packages/sqlalchemy/orm/session.py", line 1530, in _connection_for_bind
    engine, execution_options
  File "/home/airflow/.local/lib/python3.7/site-packages/sqlalchemy/orm/session.py", line 747, in _connection_for_bind
    conn = bind.connect()
  File "/home/airflow/.local/lib/python3.7/site-packages/sqlalchemy/engine/base.py", line 3197, in connect
    return self._connection_cls(self, close_with_result=close_with_result)
  File "/home/airflow/.local/lib/python3.7/site-packages/sqlalchemy/engine/base.py", line 96, in __init__
    else engine.raw_connection()
  File "/home/airflow/.local/lib/python3.7/site-packages/sqlalchemy/engine/base.py", line 3276, in raw_connection
    return self._wrap_pool_connect(self.pool.connect, _connection)
  File "/home/airflow/.local/lib/python3.7/site-packages/sqlalchemy/engine/base.py", line 3247, in _wrap_pool_connect
    e, dialect, self
  File "/home/airflow/.local/lib/python3.7/site-packages/sqlalchemy/engine/base.py", line 2101, in _handle_dbapi_exception_noconnection
    sqlalchemy_exception, with_traceback=exc_info[2], from_=e
  File "/home/airflow/.local/lib/python3.7/site-packages/sqlalchemy/util/compat.py", line 207, in raise_
    raise exception
  File "/home/airflow/.local/lib/python3.7/site-packages/sqlalchemy/engine/base.py", line 3243, in _wrap_pool_connect
    return fn()
  File "/home/airflow/.local/lib/python3.7/site-packages/sqlalchemy/pool/base.py", line 310, in connect
    return _ConnectionFairy._checkout(self)
  File "/home/airflow/.local/lib/python3.7/site-packages/sqlalchemy/pool/base.py", line 868, in _checkout
    fairy = _ConnectionRecord.checkout(pool)
  File "/home/airflow/.local/lib/python3.7/site-packages/sqlalchemy/pool/base.py", line 476, in checkout
    rec = pool._do_get()
  File "/home/airflow/.local/lib/python3.7/site-packages/sqlalchemy/pool/impl.py", line 256, in _do_get
    return self._create_connection()
  File "/home/airflow/.local/lib/python3.7/site-packages/sqlalchemy/pool/base.py", line 256, in _create_connection
    return _ConnectionRecord(self)
  File "/home/airflow/.local/lib/python3.7/site-packages/sqlalchemy/pool/base.py", line 371, in __init__
    self.__connect()
  File "/home/airflow/.local/lib/python3.7/site-packages/sqlalchemy/pool/base.py", line 666, in __connect
    pool.logger.debug("Error on connect(): %s", e)
  File "/home/airflow/.local/lib/python3.7/site-packages/sqlalchemy/util/langhelpers.py", line 72, in __exit__
    with_traceback=exc_tb,
  File "/home/airflow/.local/lib/python3.7/site-packages/sqlalchemy/util/compat.py", line 207, in raise_
    raise exception
  File "/home/airflow/.local/lib/python3.7/site-packages/sqlalchemy/pool/base.py", line 661, in __connect
    self.dbapi_connection = connection = pool._invoke_creator(self)
  File "/home/airflow/.local/lib/python3.7/site-packages/sqlalchemy/engine/create.py", line 590, in connect
    return dialect.connect(*cargs, **cparams)
  File "/home/airflow/.local/lib/python3.7/site-packages/sqlalchemy/engine/default.py", line 584, in connect
    return self.dbapi.connect(*cargs, **cparams)
  File "/home/airflow/.local/lib/python3.7/site-packages/psycopg2/__init__.py", line 122, in connect
    conn = _connect(dsn, connection_factory=connection_factory, **kwasync)
sqlalchemy.exc.OperationalError: (psycopg2.OperationalError) could not translate host name "postgres" to address: Temporary failure in name resolution

(Background on this error at: https://sqlalche.me/e/14/e3q8)
[2022-09-23T23:29:56.733+0000] {local_task_job.py:148} ERROR - Heartbeat time limit exceeded!
[2022-09-23T23:29:57.056+0000] {process_utils.py:133} INFO - Sending Signals.SIGTERM to group 7593. PIDs of all processes in the group: [7593]
[2022-09-23T23:29:57.057+0000] {process_utils.py:84} INFO - Sending the signal Signals.SIGTERM to group 7593
[2022-09-23T23:29:57.139+0000] {process_utils.py:79} INFO - Process psutil.Process(pid=7593, status='terminated', exitcode=1, started='20:52:00') (7593) terminated with exit code 1
