[2022-09-22T15:05:28.627+0000] {taskinstance.py:1165} INFO - Dependencies all met for <TaskInstance: loading_data.create_tables manual__2022-09-22T15:05:27.058407+00:00 [queued]>
[2022-09-22T15:05:28.693+0000] {taskinstance.py:1165} INFO - Dependencies all met for <TaskInstance: loading_data.create_tables manual__2022-09-22T15:05:27.058407+00:00 [queued]>
[2022-09-22T15:05:28.694+0000] {taskinstance.py:1362} INFO - 
--------------------------------------------------------------------------------
[2022-09-22T15:05:28.694+0000] {taskinstance.py:1363} INFO - Starting attempt 1 of 1
[2022-09-22T15:05:28.694+0000] {taskinstance.py:1364} INFO - 
--------------------------------------------------------------------------------
[2022-09-22T15:05:28.840+0000] {taskinstance.py:1383} INFO - Executing <Task(PythonOperator): create_tables> on 2022-09-22 15:05:27.058407+00:00
[2022-09-22T15:05:28.866+0000] {standard_task_runner.py:54} INFO - Started process 1483 to run task
[2022-09-22T15:05:28.886+0000] {standard_task_runner.py:82} INFO - Running: ['***', 'tasks', 'run', 'loading_data', 'create_tables', 'manual__2022-09-22T15:05:27.058407+00:00', '--job-id', '19', '--raw', '--subdir', 'DAGS_FOLDER/load_data.py', '--cfg-path', '/tmp/tmp8m3m9jh9']
[2022-09-22T15:05:28.887+0000] {standard_task_runner.py:83} INFO - Job 19: Subtask create_tables
[2022-09-22T15:05:28.889+0000] {dagbag.py:525} INFO - Filling up the DagBag from /opt/***/dags/load_data.py
[2022-09-22T15:05:30.450+0000] {task_command.py:384} INFO - Running <TaskInstance: loading_data.create_tables manual__2022-09-22T15:05:27.058407+00:00 [running]> on host c1ab2cb1bbac
[2022-09-22T15:05:30.748+0000] {taskinstance.py:1592} INFO - Exporting the following env vars:
AIRFLOW_CTX_DAG_OWNER=***
AIRFLOW_CTX_DAG_ID=loading_data
AIRFLOW_CTX_TASK_ID=create_tables
AIRFLOW_CTX_EXECUTION_DATE=2022-09-22T15:05:27.058407+00:00
AIRFLOW_CTX_TRY_NUMBER=1
AIRFLOW_CTX_DAG_RUN_ID=manual__2022-09-22T15:05:27.058407+00:00
[2022-09-22T15:05:30.790+0000] {logging_mixin.py:117} INFO - (psycopg2.OperationalError) connection to server at "localhost" (127.0.0.1), port 5432 failed: Connection refused
	Is the server running on that host and accepting TCP/IP connections?
connection to server at "localhost" (::1), port 5432 failed: Cannot assign requested address
	Is the server running on that host and accepting TCP/IP connections?

(Background on this error at: https://sqlalche.me/e/14/e3q8)
[2022-09-22T15:05:30.791+0000] {python.py:177} INFO - Done. Returned value was: None
[2022-09-22T15:05:30.819+0000] {taskinstance.py:1406} INFO - Marking task as SUCCESS. dag_id=loading_data, task_id=create_tables, execution_date=20220922T150527, start_date=20220922T150528, end_date=20220922T150530
[2022-09-22T15:05:30.947+0000] {local_task_job.py:164} INFO - Task exited with return code 0
[2022-09-22T15:05:31.037+0000] {local_task_job.py:273} INFO - 1 downstream tasks scheduled from follow-on schedule check
