[2022-09-23T17:09:14.247+0000] {taskinstance.py:1165} INFO - Dependencies all met for <TaskInstance: loading_data.load_traj_tables manual__2022-09-23T17:08:59.726511+00:00 [queued]>
[2022-09-23T17:09:14.381+0000] {taskinstance.py:1165} INFO - Dependencies all met for <TaskInstance: loading_data.load_traj_tables manual__2022-09-23T17:08:59.726511+00:00 [queued]>
[2022-09-23T17:09:14.382+0000] {taskinstance.py:1362} INFO - 
--------------------------------------------------------------------------------
[2022-09-23T17:09:14.382+0000] {taskinstance.py:1363} INFO - Starting attempt 1 of 1
[2022-09-23T17:09:14.383+0000] {taskinstance.py:1364} INFO - 
--------------------------------------------------------------------------------
[2022-09-23T17:09:15.018+0000] {taskinstance.py:1383} INFO - Executing <Task(PythonOperator): load_traj_tables> on 2022-09-23 17:08:59.726511+00:00
[2022-09-23T17:09:15.028+0000] {standard_task_runner.py:54} INFO - Started process 622 to run task
[2022-09-23T17:09:15.044+0000] {standard_task_runner.py:82} INFO - Running: ['***', 'tasks', 'run', 'loading_data', 'load_traj_tables', 'manual__2022-09-23T17:08:59.726511+00:00', '--job-id', '133', '--raw', '--subdir', 'DAGS_FOLDER/load_data.py', '--cfg-path', '/tmp/tmpzzede_vh']
[2022-09-23T17:09:15.045+0000] {standard_task_runner.py:83} INFO - Job 133: Subtask load_traj_tables
[2022-09-23T17:09:15.047+0000] {dagbag.py:525} INFO - Filling up the DagBag from /opt/***/dags/load_data.py
[2022-09-23T17:09:17.032+0000] {task_command.py:384} INFO - Running <TaskInstance: loading_data.load_traj_tables manual__2022-09-23T17:08:59.726511+00:00 [running]> on host 211e88f8c2ad
[2022-09-23T17:09:17.347+0000] {taskinstance.py:1592} INFO - Exporting the following env vars:
AIRFLOW_CTX_DAG_OWNER=***
AIRFLOW_CTX_DAG_ID=loading_data
AIRFLOW_CTX_TASK_ID=load_traj_tables
AIRFLOW_CTX_EXECUTION_DATE=2022-09-23T17:08:59.726511+00:00
AIRFLOW_CTX_TRY_NUMBER=1
AIRFLOW_CTX_DAG_RUN_ID=manual__2022-09-23T17:08:59.726511+00:00
[2022-09-23T17:21:58.398+0000] {base_job.py:232} ERROR - LocalTaskJob heartbeat got an exception
Traceback (most recent call last):
  File "/home/airflow/.local/lib/python3.7/site-packages/sqlalchemy/engine/base.py", line 3243, in _wrap_pool_connect
    return fn()
  File "/home/airflow/.local/lib/python3.7/site-packages/sqlalchemy/pool/base.py", line 310, in connect
    return _ConnectionFairy._checkout(self)
  File "/home/airflow/.local/lib/python3.7/site-packages/sqlalchemy/pool/base.py", line 868, in _checkout
    fairy = _ConnectionRecord.checkout(pool)
  File "/home/airflow/.local/lib/python3.7/site-packages/sqlalchemy/pool/base.py", line 476, in checkout
    rec = pool._do_get()
  File "/home/airflow/.local/lib/python3.7/site-packages/sqlalchemy/pool/impl.py", line 256, in _do_get
    return self._create_connection()
  File "/home/airflow/.local/lib/python3.7/site-packages/sqlalchemy/pool/base.py", line 256, in _create_connection
    return _ConnectionRecord(self)
  File "/home/airflow/.local/lib/python3.7/site-packages/sqlalchemy/pool/base.py", line 371, in __init__
    self.__connect()
  File "/home/airflow/.local/lib/python3.7/site-packages/sqlalchemy/pool/base.py", line 666, in __connect
    pool.logger.debug("Error on connect(): %s", e)
  File "/home/airflow/.local/lib/python3.7/site-packages/sqlalchemy/util/langhelpers.py", line 72, in __exit__
    with_traceback=exc_tb,
  File "/home/airflow/.local/lib/python3.7/site-packages/sqlalchemy/util/compat.py", line 207, in raise_
    raise exception
  File "/home/airflow/.local/lib/python3.7/site-packages/sqlalchemy/pool/base.py", line 661, in __connect
    self.dbapi_connection = connection = pool._invoke_creator(self)
  File "/home/airflow/.local/lib/python3.7/site-packages/sqlalchemy/engine/create.py", line 590, in connect
    return dialect.connect(*cargs, **cparams)
  File "/home/airflow/.local/lib/python3.7/site-packages/sqlalchemy/engine/default.py", line 584, in connect
    return self.dbapi.connect(*cargs, **cparams)
  File "/home/airflow/.local/lib/python3.7/site-packages/psycopg2/__init__.py", line 122, in connect
    conn = _connect(dsn, connection_factory=connection_factory, **kwasync)
psycopg2.OperationalError: could not translate host name "postgres" to address: Temporary failure in name resolution


The above exception was the direct cause of the following exception:

Traceback (most recent call last):
  File "/home/airflow/.local/lib/python3.7/site-packages/airflow/jobs/base_job.py", line 222, in heartbeat
    session.merge(self)
  File "/home/airflow/.local/lib/python3.7/site-packages/sqlalchemy/orm/session.py", line 2961, in merge
    _resolve_conflict_map=_resolve_conflict_map,
  File "/home/airflow/.local/lib/python3.7/site-packages/sqlalchemy/orm/session.py", line 3039, in _merge
    options=options,
  File "/home/airflow/.local/lib/python3.7/site-packages/sqlalchemy/orm/session.py", line 2775, in get
    identity_token=identity_token,
  File "/home/airflow/.local/lib/python3.7/site-packages/sqlalchemy/orm/session.py", line 2878, in _get_impl
    load_options=load_options,
  File "/home/airflow/.local/lib/python3.7/site-packages/sqlalchemy/orm/loading.py", line 534, in load_on_pk_identity
    bind_arguments=bind_arguments,
  File "/home/airflow/.local/lib/python3.7/site-packages/sqlalchemy/orm/session.py", line 1688, in execute
    conn = self._connection_for_bind(bind)
  File "/home/airflow/.local/lib/python3.7/site-packages/sqlalchemy/orm/session.py", line 1530, in _connection_for_bind
    engine, execution_options
  File "/home/airflow/.local/lib/python3.7/site-packages/sqlalchemy/orm/session.py", line 747, in _connection_for_bind
    conn = bind.connect()
  File "/home/airflow/.local/lib/python3.7/site-packages/sqlalchemy/engine/base.py", line 3197, in connect
    return self._connection_cls(self, close_with_result=close_with_result)
  File "/home/airflow/.local/lib/python3.7/site-packages/sqlalchemy/engine/base.py", line 96, in __init__
    else engine.raw_connection()
  File "/home/airflow/.local/lib/python3.7/site-packages/sqlalchemy/engine/base.py", line 3276, in raw_connection
    return self._wrap_pool_connect(self.pool.connect, _connection)
  File "/home/airflow/.local/lib/python3.7/site-packages/sqlalchemy/engine/base.py", line 3247, in _wrap_pool_connect
    e, dialect, self
  File "/home/airflow/.local/lib/python3.7/site-packages/sqlalchemy/engine/base.py", line 2101, in _handle_dbapi_exception_noconnection
    sqlalchemy_exception, with_traceback=exc_info[2], from_=e
  File "/home/airflow/.local/lib/python3.7/site-packages/sqlalchemy/util/compat.py", line 207, in raise_
    raise exception
  File "/home/airflow/.local/lib/python3.7/site-packages/sqlalchemy/engine/base.py", line 3243, in _wrap_pool_connect
    return fn()
  File "/home/airflow/.local/lib/python3.7/site-packages/sqlalchemy/pool/base.py", line 310, in connect
    return _ConnectionFairy._checkout(self)
  File "/home/airflow/.local/lib/python3.7/site-packages/sqlalchemy/pool/base.py", line 868, in _checkout
    fairy = _ConnectionRecord.checkout(pool)
  File "/home/airflow/.local/lib/python3.7/site-packages/sqlalchemy/pool/base.py", line 476, in checkout
    rec = pool._do_get()
  File "/home/airflow/.local/lib/python3.7/site-packages/sqlalchemy/pool/impl.py", line 256, in _do_get
    return self._create_connection()
  File "/home/airflow/.local/lib/python3.7/site-packages/sqlalchemy/pool/base.py", line 256, in _create_connection
    return _ConnectionRecord(self)
  File "/home/airflow/.local/lib/python3.7/site-packages/sqlalchemy/pool/base.py", line 371, in __init__
    self.__connect()
  File "/home/airflow/.local/lib/python3.7/site-packages/sqlalchemy/pool/base.py", line 666, in __connect
    pool.logger.debug("Error on connect(): %s", e)
  File "/home/airflow/.local/lib/python3.7/site-packages/sqlalchemy/util/langhelpers.py", line 72, in __exit__
    with_traceback=exc_tb,
  File "/home/airflow/.local/lib/python3.7/site-packages/sqlalchemy/util/compat.py", line 207, in raise_
    raise exception
  File "/home/airflow/.local/lib/python3.7/site-packages/sqlalchemy/pool/base.py", line 661, in __connect
    self.dbapi_connection = connection = pool._invoke_creator(self)
  File "/home/airflow/.local/lib/python3.7/site-packages/sqlalchemy/engine/create.py", line 590, in connect
    return dialect.connect(*cargs, **cparams)
  File "/home/airflow/.local/lib/python3.7/site-packages/sqlalchemy/engine/default.py", line 584, in connect
    return self.dbapi.connect(*cargs, **cparams)
  File "/home/airflow/.local/lib/python3.7/site-packages/psycopg2/__init__.py", line 122, in connect
    conn = _connect(dsn, connection_factory=connection_factory, **kwasync)
sqlalchemy.exc.OperationalError: (psycopg2.OperationalError) could not translate host name "postgres" to address: Temporary failure in name resolution

(Background on this error at: https://sqlalche.me/e/14/e3q8)
[2022-09-23T18:01:08.457+0000] {local_task_job.py:148} ERROR - Heartbeat time limit exceeded!
[2022-09-23T18:01:09.585+0000] {process_utils.py:133} INFO - Sending Signals.SIGTERM to group 622. PIDs of all processes in the group: [622]
[2022-09-23T18:01:09.740+0000] {process_utils.py:84} INFO - Sending the signal Signals.SIGTERM to group 622
[2022-09-23T18:01:13.247+0000] {taskinstance.py:1562} ERROR - Received SIGTERM. Terminating subprocesses.
[2022-09-23T18:01:35.789+0000] {logging_mixin.py:117} INFO - Failed  ---- (***.exceptions.AirflowException) Task received SIGTERM signal
[SQL: INSERT INTO trajectories (track_id, " lat", " lon", " speed", " lon_acc", " lat_acc", " time", id) VALUES (%(track_id)s, %( lat)s, %( lon)s, %( speed)s, %( lon_acc)s, %( lat_acc)s, %( time)s, %(id)s)]
[parameters: [{'track_id': '_1', ' lat': ' 37.977391', ' lon': 23.737688, ' speed': 4.9178, ' lon_acc': 0.0518, ' lat_acc': -0.0299, ' time': 0.0, 'id': 1}, {'trac ... (217188689 characters truncated) ... .8, 'id': 1447808}, {'track_id': '_922', ' lat': ' ', ' lon': None, ' speed': None, ' lon_acc': None, ' lat_acc': None, ' time': None, 'id': 1447809}]]
[2022-09-23T18:01:36.011+0000] {python.py:177} INFO - Done. Returned value was: None
[2022-09-23T18:01:37.487+0000] {taskinstance.py:1406} INFO - Marking task as SUCCESS. dag_id=loading_data, task_id=load_traj_tables, execution_date=20220923T170859, start_date=20220923T170914, end_date=20220923T180137
[2022-09-23T18:01:37.699+0000] {process_utils.py:79} INFO - Process psutil.Process(pid=622, status='terminated', exitcode=0, started='17:09:14') (622) terminated with exit code 0
