[2022-09-22T14:38:22.407+0000] {taskinstance.py:1165} INFO - Dependencies all met for <TaskInstance: loading_data.create_tables manual__2022-09-22T14:38:20.747027+00:00 [queued]>
[2022-09-22T14:38:22.432+0000] {taskinstance.py:1165} INFO - Dependencies all met for <TaskInstance: loading_data.create_tables manual__2022-09-22T14:38:20.747027+00:00 [queued]>
[2022-09-22T14:38:22.432+0000] {taskinstance.py:1362} INFO - 
--------------------------------------------------------------------------------
[2022-09-22T14:38:22.432+0000] {taskinstance.py:1363} INFO - Starting attempt 1 of 1
[2022-09-22T14:38:22.433+0000] {taskinstance.py:1364} INFO - 
--------------------------------------------------------------------------------
[2022-09-22T14:38:22.487+0000] {taskinstance.py:1383} INFO - Executing <Task(PythonOperator): create_tables> on 2022-09-22 14:38:20.747027+00:00
[2022-09-22T14:38:22.498+0000] {standard_task_runner.py:54} INFO - Started process 377 to run task
[2022-09-22T14:38:22.507+0000] {standard_task_runner.py:82} INFO - Running: ['***', 'tasks', 'run', 'loading_data', 'create_tables', 'manual__2022-09-22T14:38:20.747027+00:00', '--job-id', '15', '--raw', '--subdir', 'DAGS_FOLDER/load_data.py', '--cfg-path', '/tmp/tmp48em5wur']
[2022-09-22T14:38:22.508+0000] {standard_task_runner.py:83} INFO - Job 15: Subtask create_tables
[2022-09-22T14:38:22.510+0000] {dagbag.py:525} INFO - Filling up the DagBag from /opt/***/dags/load_data.py
[2022-09-22T14:38:25.854+0000] {task_command.py:384} INFO - Running <TaskInstance: loading_data.create_tables manual__2022-09-22T14:38:20.747027+00:00 [running]> on host c1ab2cb1bbac
[2022-09-22T14:38:26.597+0000] {taskinstance.py:1592} INFO - Exporting the following env vars:
AIRFLOW_CTX_DAG_OWNER=***
AIRFLOW_CTX_DAG_ID=loading_data
AIRFLOW_CTX_TASK_ID=create_tables
AIRFLOW_CTX_EXECUTION_DATE=2022-09-22T14:38:20.747027+00:00
AIRFLOW_CTX_TRY_NUMBER=1
AIRFLOW_CTX_DAG_RUN_ID=manual__2022-09-22T14:38:20.747027+00:00
[2022-09-22T14:38:26.609+0000] {logging_mixin.py:117} INFO - (psycopg2.OperationalError) could not translate host name "host.docker.internal" to address: Name or service not known

(Background on this error at: https://sqlalche.me/e/14/e3q8)
[2022-09-22T14:38:26.610+0000] {python.py:177} INFO - Done. Returned value was: None
[2022-09-22T14:38:26.630+0000] {taskinstance.py:1406} INFO - Marking task as SUCCESS. dag_id=loading_data, task_id=create_tables, execution_date=20220922T143820, start_date=20220922T143822, end_date=20220922T143826
[2022-09-22T14:38:27.039+0000] {local_task_job.py:164} INFO - Task exited with return code 0
[2022-09-22T14:38:27.217+0000] {local_task_job.py:273} INFO - 1 downstream tasks scheduled from follow-on schedule check
