[2022-09-22T21:14:43.736+0000] {taskinstance.py:1165} INFO - Dependencies all met for <TaskInstance: loading_data.insert_data manual__2022-09-22T21:14:31.491248+00:00 [queued]>
[2022-09-22T21:14:43.782+0000] {taskinstance.py:1165} INFO - Dependencies all met for <TaskInstance: loading_data.insert_data manual__2022-09-22T21:14:31.491248+00:00 [queued]>
[2022-09-22T21:14:43.783+0000] {taskinstance.py:1362} INFO - 
--------------------------------------------------------------------------------
[2022-09-22T21:14:43.783+0000] {taskinstance.py:1363} INFO - Starting attempt 1 of 1
[2022-09-22T21:14:43.783+0000] {taskinstance.py:1364} INFO - 
--------------------------------------------------------------------------------
[2022-09-22T21:14:43.877+0000] {taskinstance.py:1383} INFO - Executing <Task(PythonOperator): insert_data> on 2022-09-22 21:14:31.491248+00:00
[2022-09-22T21:14:43.884+0000] {standard_task_runner.py:54} INFO - Started process 17057 to run task
[2022-09-22T21:14:43.897+0000] {standard_task_runner.py:82} INFO - Running: ['***', 'tasks', 'run', 'loading_data', 'insert_data', 'manual__2022-09-22T21:14:31.491248+00:00', '--job-id', '50', '--raw', '--subdir', 'DAGS_FOLDER/load_data.py', '--cfg-path', '/tmp/tmpquhi07fc']
[2022-09-22T21:14:43.898+0000] {standard_task_runner.py:83} INFO - Job 50: Subtask insert_data
[2022-09-22T21:14:43.900+0000] {dagbag.py:525} INFO - Filling up the DagBag from /opt/***/dags/load_data.py
[2022-09-22T21:14:46.799+0000] {task_command.py:384} INFO - Running <TaskInstance: loading_data.insert_data manual__2022-09-22T21:14:31.491248+00:00 [running]> on host c1ab2cb1bbac
[2022-09-22T21:14:47.078+0000] {taskinstance.py:1592} INFO - Exporting the following env vars:
AIRFLOW_CTX_DAG_OWNER=***
AIRFLOW_CTX_DAG_ID=loading_data
AIRFLOW_CTX_TASK_ID=insert_data
AIRFLOW_CTX_EXECUTION_DATE=2022-09-22T21:14:31.491248+00:00
AIRFLOW_CTX_TRY_NUMBER=1
AIRFLOW_CTX_DAG_RUN_ID=manual__2022-09-22T21:14:31.491248+00:00
[2022-09-22T21:14:47.081+0000] {taskinstance.py:1851} ERROR - Task failed with exception
Traceback (most recent call last):
  File "/home/airflow/.local/lib/python3.7/site-packages/airflow/operators/python.py", line 175, in execute
    return_value = self.execute_callable()
  File "/home/airflow/.local/lib/python3.7/site-packages/airflow/operators/python.py", line 193, in execute_callable
    return self.python_callable(*self.op_args, **self.op_kwargs)
  File "/opt/airflow/dags/load_data.py", line 38, in insert_to_table
    create_engine()
TypeError: create_engine() missing 1 required positional argument: 'url'
[2022-09-22T21:14:47.112+0000] {taskinstance.py:1406} INFO - Marking task as FAILED. dag_id=loading_data, task_id=insert_data, execution_date=20220922T211431, start_date=20220922T211443, end_date=20220922T211447
[2022-09-22T21:14:47.155+0000] {standard_task_runner.py:107} ERROR - Failed to execute job 50 for task insert_data (create_engine() missing 1 required positional argument: 'url'; 17057)
[2022-09-22T21:14:47.188+0000] {local_task_job.py:164} INFO - Task exited with return code 1
[2022-09-22T21:14:47.261+0000] {local_task_job.py:273} INFO - 0 downstream tasks scheduled from follow-on schedule check
