[2022-09-22T14:38:07.436+0000] {taskinstance.py:1165} INFO - Dependencies all met for <TaskInstance: loading_data.create_tables scheduled__2022-01-01T00:00:00+00:00 [queued]>
[2022-09-22T14:38:07.469+0000] {taskinstance.py:1165} INFO - Dependencies all met for <TaskInstance: loading_data.create_tables scheduled__2022-01-01T00:00:00+00:00 [queued]>
[2022-09-22T14:38:07.470+0000] {taskinstance.py:1362} INFO - 
--------------------------------------------------------------------------------
[2022-09-22T14:38:07.470+0000] {taskinstance.py:1363} INFO - Starting attempt 1 of 1
[2022-09-22T14:38:07.470+0000] {taskinstance.py:1364} INFO - 
--------------------------------------------------------------------------------
[2022-09-22T14:38:07.541+0000] {taskinstance.py:1383} INFO - Executing <Task(PythonOperator): create_tables> on 2022-01-01 00:00:00+00:00
[2022-09-22T14:38:07.555+0000] {standard_task_runner.py:54} INFO - Started process 362 to run task
[2022-09-22T14:38:07.559+0000] {standard_task_runner.py:82} INFO - Running: ['***', 'tasks', 'run', 'loading_data', 'create_tables', 'scheduled__2022-01-01T00:00:00+00:00', '--job-id', '13', '--raw', '--subdir', 'DAGS_FOLDER/load_data.py', '--cfg-path', '/tmp/tmp314ztcy_']
[2022-09-22T14:38:07.560+0000] {standard_task_runner.py:83} INFO - Job 13: Subtask create_tables
[2022-09-22T14:38:07.569+0000] {dagbag.py:525} INFO - Filling up the DagBag from /opt/***/dags/load_data.py
[2022-09-22T14:38:13.506+0000] {task_command.py:384} INFO - Running <TaskInstance: loading_data.create_tables scheduled__2022-01-01T00:00:00+00:00 [running]> on host c1ab2cb1bbac
[2022-09-22T14:38:13.770+0000] {taskinstance.py:1592} INFO - Exporting the following env vars:
AIRFLOW_CTX_DAG_OWNER=***
AIRFLOW_CTX_DAG_ID=loading_data
AIRFLOW_CTX_TASK_ID=create_tables
AIRFLOW_CTX_EXECUTION_DATE=2022-01-01T00:00:00+00:00
AIRFLOW_CTX_TRY_NUMBER=1
AIRFLOW_CTX_DAG_RUN_ID=scheduled__2022-01-01T00:00:00+00:00
[2022-09-22T14:38:13.933+0000] {logging_mixin.py:117} INFO - (psycopg2.OperationalError) could not translate host name "host.docker.internal" to address: Name or service not known

(Background on this error at: https://sqlalche.me/e/14/e3q8)
[2022-09-22T14:38:13.933+0000] {python.py:177} INFO - Done. Returned value was: None
[2022-09-22T14:38:13.969+0000] {taskinstance.py:1406} INFO - Marking task as SUCCESS. dag_id=loading_data, task_id=create_tables, execution_date=20220101T000000, start_date=20220922T143807, end_date=20220922T143813
[2022-09-22T14:38:14.089+0000] {local_task_job.py:164} INFO - Task exited with return code 0
[2022-09-22T14:38:14.195+0000] {local_task_job.py:273} INFO - 1 downstream tasks scheduled from follow-on schedule check
