[2022-09-22T21:13:06.938+0000] {taskinstance.py:1165} INFO - Dependencies all met for <TaskInstance: loading_data.create_tables manual__2022-09-22T21:13:03.966100+00:00 [queued]>
[2022-09-22T21:13:06.973+0000] {taskinstance.py:1165} INFO - Dependencies all met for <TaskInstance: loading_data.create_tables manual__2022-09-22T21:13:03.966100+00:00 [queued]>
[2022-09-22T21:13:06.973+0000] {taskinstance.py:1362} INFO - 
--------------------------------------------------------------------------------
[2022-09-22T21:13:06.974+0000] {taskinstance.py:1363} INFO - Starting attempt 1 of 1
[2022-09-22T21:13:06.974+0000] {taskinstance.py:1364} INFO - 
--------------------------------------------------------------------------------
[2022-09-22T21:13:07.038+0000] {taskinstance.py:1383} INFO - Executing <Task(PythonOperator): create_tables> on 2022-09-22 21:13:03.966100+00:00
[2022-09-22T21:13:07.052+0000] {standard_task_runner.py:54} INFO - Started process 17006 to run task
[2022-09-22T21:13:07.065+0000] {standard_task_runner.py:82} INFO - Running: ['***', 'tasks', 'run', 'loading_data', 'create_tables', 'manual__2022-09-22T21:13:03.966100+00:00', '--job-id', '47', '--raw', '--subdir', 'DAGS_FOLDER/load_data.py', '--cfg-path', '/tmp/tmpl2ckkfki']
[2022-09-22T21:13:07.066+0000] {standard_task_runner.py:83} INFO - Job 47: Subtask create_tables
[2022-09-22T21:13:07.069+0000] {dagbag.py:525} INFO - Filling up the DagBag from /opt/***/dags/load_data.py
[2022-09-22T21:13:09.825+0000] {task_command.py:384} INFO - Running <TaskInstance: loading_data.create_tables manual__2022-09-22T21:13:03.966100+00:00 [running]> on host c1ab2cb1bbac
[2022-09-22T21:13:10.121+0000] {taskinstance.py:1592} INFO - Exporting the following env vars:
AIRFLOW_CTX_DAG_OWNER=***
AIRFLOW_CTX_DAG_ID=loading_data
AIRFLOW_CTX_TASK_ID=create_tables
AIRFLOW_CTX_EXECUTION_DATE=2022-09-22T21:13:03.966100+00:00
AIRFLOW_CTX_TRY_NUMBER=1
AIRFLOW_CTX_DAG_RUN_ID=manual__2022-09-22T21:13:03.966100+00:00
[2022-09-22T21:13:10.147+0000] {logging_mixin.py:117} INFO - [Errno 2] No such file or directory: 'TRACJECTORIES_schema.sql'
[2022-09-22T21:13:10.147+0000] {python.py:177} INFO - Done. Returned value was: None
[2022-09-22T21:13:10.171+0000] {taskinstance.py:1406} INFO - Marking task as SUCCESS. dag_id=loading_data, task_id=create_tables, execution_date=20220922T211303, start_date=20220922T211306, end_date=20220922T211310
[2022-09-22T21:13:10.292+0000] {local_task_job.py:164} INFO - Task exited with return code 0
[2022-09-22T21:13:10.431+0000] {local_task_job.py:273} INFO - 1 downstream tasks scheduled from follow-on schedule check
