[2022-09-23T00:30:33.126+0000] {taskinstance.py:1165} INFO - Dependencies all met for <TaskInstance: loading_data.create_tables manual__2022-09-23T00:30:28.917145+00:00 [queued]>
[2022-09-23T00:30:33.171+0000] {taskinstance.py:1165} INFO - Dependencies all met for <TaskInstance: loading_data.create_tables manual__2022-09-23T00:30:28.917145+00:00 [queued]>
[2022-09-23T00:30:33.171+0000] {taskinstance.py:1362} INFO - 
--------------------------------------------------------------------------------
[2022-09-23T00:30:33.172+0000] {taskinstance.py:1363} INFO - Starting attempt 1 of 1
[2022-09-23T00:30:33.172+0000] {taskinstance.py:1364} INFO - 
--------------------------------------------------------------------------------
[2022-09-23T00:30:33.247+0000] {taskinstance.py:1383} INFO - Executing <Task(PythonOperator): create_tables> on 2022-09-23 00:30:28.917145+00:00
[2022-09-23T00:30:33.259+0000] {standard_task_runner.py:54} INFO - Started process 295 to run task
[2022-09-23T00:30:33.270+0000] {standard_task_runner.py:82} INFO - Running: ['***', 'tasks', 'run', 'loading_data', 'create_tables', 'manual__2022-09-23T00:30:28.917145+00:00', '--job-id', '115', '--raw', '--subdir', 'DAGS_FOLDER/load_data.py', '--cfg-path', '/tmp/tmp3l2l8bb9']
[2022-09-23T00:30:33.271+0000] {standard_task_runner.py:83} INFO - Job 115: Subtask create_tables
[2022-09-23T00:30:33.298+0000] {dagbag.py:525} INFO - Filling up the DagBag from /opt/***/dags/load_data.py
[2022-09-23T00:30:42.352+0000] {task_command.py:384} INFO - Running <TaskInstance: loading_data.create_tables manual__2022-09-23T00:30:28.917145+00:00 [running]> on host 211e88f8c2ad
[2022-09-23T00:30:43.004+0000] {taskinstance.py:1592} INFO - Exporting the following env vars:
AIRFLOW_CTX_DAG_OWNER=***
AIRFLOW_CTX_DAG_ID=loading_data
AIRFLOW_CTX_TASK_ID=create_tables
AIRFLOW_CTX_EXECUTION_DATE=2022-09-23T00:30:28.917145+00:00
AIRFLOW_CTX_TRY_NUMBER=1
AIRFLOW_CTX_DAG_RUN_ID=manual__2022-09-23T00:30:28.917145+00:00
[2022-09-23T00:30:43.048+0000] {logging_mixin.py:117} INFO - (psycopg2.OperationalError) connection to server at "postgres" (172.18.0.2), port 5432 failed: FATAL:  database "trafficdatabase" does not exist

(Background on this error at: https://sqlalche.me/e/14/e3q8)
[2022-09-23T00:30:43.049+0000] {python.py:177} INFO - Done. Returned value was: None
[2022-09-23T00:30:43.094+0000] {taskinstance.py:1406} INFO - Marking task as SUCCESS. dag_id=loading_data, task_id=create_tables, execution_date=20220923T003028, start_date=20220923T003033, end_date=20220923T003043
[2022-09-23T00:30:43.235+0000] {local_task_job.py:164} INFO - Task exited with return code 0
[2022-09-23T00:30:43.391+0000] {local_task_job.py:273} INFO - 1 downstream tasks scheduled from follow-on schedule check
