[2022-09-22T20:48:51.609+0000] {taskinstance.py:1165} INFO - Dependencies all met for <TaskInstance: loading_data.insert_data manual__2022-09-22T20:48:44.675905+00:00 [queued]>
[2022-09-22T20:48:51.633+0000] {taskinstance.py:1165} INFO - Dependencies all met for <TaskInstance: loading_data.insert_data manual__2022-09-22T20:48:44.675905+00:00 [queued]>
[2022-09-22T20:48:51.633+0000] {taskinstance.py:1362} INFO - 
--------------------------------------------------------------------------------
[2022-09-22T20:48:51.633+0000] {taskinstance.py:1363} INFO - Starting attempt 1 of 1
[2022-09-22T20:48:51.634+0000] {taskinstance.py:1364} INFO - 
--------------------------------------------------------------------------------
[2022-09-22T20:48:51.677+0000] {taskinstance.py:1383} INFO - Executing <Task(PythonOperator): insert_data> on 2022-09-22 20:48:44.675905+00:00
[2022-09-22T20:48:51.684+0000] {standard_task_runner.py:54} INFO - Started process 16080 to run task
[2022-09-22T20:48:51.689+0000] {standard_task_runner.py:82} INFO - Running: ['***', 'tasks', 'run', 'loading_data', 'insert_data', 'manual__2022-09-22T20:48:44.675905+00:00', '--job-id', '38', '--raw', '--subdir', 'DAGS_FOLDER/load_data.py', '--cfg-path', '/tmp/tmpd6v9v8us']
[2022-09-22T20:48:51.694+0000] {standard_task_runner.py:83} INFO - Job 38: Subtask insert_data
[2022-09-22T20:48:51.695+0000] {dagbag.py:525} INFO - Filling up the DagBag from /opt/***/dags/load_data.py
[2022-09-22T20:48:52.702+0000] {task_command.py:384} INFO - Running <TaskInstance: loading_data.insert_data manual__2022-09-22T20:48:44.675905+00:00 [running]> on host c1ab2cb1bbac
[2022-09-22T20:48:53.437+0000] {taskinstance.py:1592} INFO - Exporting the following env vars:
AIRFLOW_CTX_DAG_OWNER=***
AIRFLOW_CTX_DAG_ID=loading_data
AIRFLOW_CTX_TASK_ID=insert_data
AIRFLOW_CTX_EXECUTION_DATE=2022-09-22T20:48:44.675905+00:00
AIRFLOW_CTX_TRY_NUMBER=1
AIRFLOW_CTX_DAG_RUN_ID=manual__2022-09-22T20:48:44.675905+00:00
[2022-09-22T20:48:53.438+0000] {taskinstance.py:1851} ERROR - Task failed with exception
Traceback (most recent call last):
  File "/home/airflow/.local/lib/python3.7/site-packages/airflow/operators/python.py", line 175, in execute
    return_value = self.execute_callable()
  File "/home/airflow/.local/lib/python3.7/site-packages/airflow/operators/python.py", line 193, in execute_callable
    return self.python_callable(*self.op_args, **self.op_kwargs)
  File "/opt/airflow/dags/load_data.py", line 36, in insert_to_table
    create_engine()
TypeError: create_engine() missing 1 required positional argument: 'url'
[2022-09-22T20:48:53.543+0000] {taskinstance.py:1406} INFO - Marking task as FAILED. dag_id=loading_data, task_id=insert_data, execution_date=20220922T204844, start_date=20220922T204851, end_date=20220922T204853
[2022-09-22T20:48:53.844+0000] {standard_task_runner.py:107} ERROR - Failed to execute job 38 for task insert_data (create_engine() missing 1 required positional argument: 'url'; 16080)
[2022-09-22T20:48:53.869+0000] {local_task_job.py:164} INFO - Task exited with return code 1
[2022-09-22T20:48:53.983+0000] {local_task_job.py:273} INFO - 0 downstream tasks scheduled from follow-on schedule check
